Workbook

Sheet STATEMENT
B2: ATLAS HONDA LIMITED
B4: Statement of Financial Position | G4: Statement of Profit or Loss
B5: As at March 31, 2025 | G5: For the year ended March 31, 2025
C6: 2023 | D6: 2024 | E6: 2025 | G6: Particulars | H6: 2023 | I6: 2024 | J6: 2025
B7: Assets | G7: Sales | H7: 135485652 | I7: 159292229 | J7: 203894438
B8: Non Current Assets | G8: Cost of sales | H8: 125813871 | I8: 147065100 | J8: 181714342
B9: Property, plant & equipment | C9: 12158765 | D9: 12445718 | E9: 12629323 | G9: Gross Profit | H9: 9671781 | I9: 12227129 | J9: 22180096
B10: Intangible asset | C10: 35311 | D10: 7826 | E10: 23959 | G10: Sales and marketing expenses | H10: -3032096 | I10: -3651933 | J10: -4408844
B11: Long term investments | C11: 340816 | D11: 350593 | E11: 400519 | G11: Administrative expenses | H11: -860548 | I11: -1073333 | J11: -1306075
B12: Long term loans and advances | C12: 75469 | D12: 106531 | E12: 119841 | G12: Other income | H12: 4555670 | I12: 9061152 | J12: 9192365
B13: Long term deposits | C13: 41662 | D13: 41672 | E13: 43887 | G13: Other operating expenses | H13: -2156059 | I13: -735293 | J13: -1245028
B14: Total non current assets | C14: 12652023 | D14: 12952340 | E14: 13217529 | G14: Share of profit of an Associated Company - net of tax | H14: 322 | I14: 12475 | J14: 54638
B15: Current Assets | G15: Profit from operations | H15: 8179070 | I15: 15840197 | J15: 24467152
B16: Stores, spares and loose tools | C16: 1083666 | D16: 1027714 | E16: 993123 | G16: Finance cost | H16: -76027 | I16: -102099 | J16: -125485
B17: Stock in trade | C17: 8005452 | D17: 9621651 | E17: 8369639 | G17: Profit before taxation | H17: 8103043 | I17: 15738098 | J17: 24341667
B18: Trade debts | C18: 797382 | D18: 1021954 | E18: 2506086 | G18: Taxation and Levies | H18: -3098888 | I18: -6030053 | J18: -9090052
B19: Loans and advances | C19: 94502 | D19: 89211 | E19: 102015 | G19: Profit after taxation | H19: 5004155 | I19: 9708045 | J19: 15251615
B20: Trade deposits and prepayments | C20: 2242128 | D20: 229118 | E20: 290415
B21: Short term investments | C21: 10114241 | D21: 13959667 | E21: 30048664
B22: Accrued mark-up/interest | C22: 343803 | D22: 656355 | E22: 1063361
B23: Other receivables | C23: 1874 | D23: 16137 | E23: 650643
B24: Taxation - net | E24: 811 | G24: Registration Number | H24: Group Memebers
B25: Bank balances | C25: 34702516 | D25: 36369606 | E25: 30099343 | G25: FA23-BBD-060 | H25: Iqra Mubeen
B26: Total current assets | C26: 57385564 | D26: 62991413 | E26: 74124100 | G26: FA23-BBD-086 | H26: M. Anas Nasir
B27: Total assets | C27: 70037587 | D27: 75943753 | E27: 87341629 | G27: FA24-BBD-079 | H27: Laiba Farid
B28: Equity & Liabilities | G28: FA24-BBD-175 | H28: Ryaan Amir
B29: Equity | G29: FA24-BBD-028 | H29: Aniq Abrar
B30: Share capital | C30: 1240879 | D30: 1240879 | E30: 1240879 | G30: FA24-BBD-173 | H30: Rohaan Awais
B31: Reserves | C31: 21539063 | D31: 27526690 | E31: 35121659
B32: Total equity | C32: 22779942 | D32: 28767569 | E32: 36362538
B33: Non Current Liabilities
B34: Lease liabilities | C34: 148102 | D34: 289306 | E34: 355322
B35: Staff retirement benefits | C35: 559591 | D35: 663559 | E35: 743615
B36: Deferred taxation | C36: 633022 | D36: 877658 | E36: 927367
B37: Total non current liabilities | C37: 1340715 | D37: 1830523 | E37: 2026304
B38: Current Liabilities
B39: Current portion of lease liabilities | C39: 53617 | D39: 57987 | E39: 52285
B40: Trade and other payables | C40: 45813308 | D40: 44049984 | E40: 48900502
B41: Taxation - net | C41: 50005 | D41: 1237690
B42: Total current liabilities | C42: 45916930 | D42: 45345661 | E42: 48952787
...

Sheet RATIOS
M1: Activity Ratio
A2: Liquidity Ratios | G2: Profitability Ratios | N2: Atlas Honda Limited | Q2: Indus Motors
B3: Atlas Honda Limited | E3: Indus Motors | H3: Atlas Honda Limited | K3: Indus Motors | N3: 2023 | O3: 2024 | P3: 2025 | Q3: 2025
B4: 2023 | C4: 2024 | D4: 2025 | E4: 2025 | H4: 2023 | I4: 2024 | J4: 2025 | K4: 2025 | M4: The receivable turnover (RT) | N4: =STATEMENT!H7/STATEMENT!C18 -> 169.91311 | O4: =STATEMENT!I7/STATEMENT!D18 -> 155.87025 | P4: =STATEMENT!J7/STATEMENT!E18 -> 81.359713 | Q4: 13 | R4: net sales/ trade debts
A5: Current Ratio | B5: =STATEMENT!C26/STATEMENT!C42 -> 1.2497692 | C5: =STATEMENT!D26/STATEMENT!D42 -> 1.3891387 | D5: =STATEMENT!E26/STATEMENT!E42 -> 1.5141957 | E5: 1.5 | G5: gross profit margin | H5: =STATEMENT!H9/STATEMENT!H7 -> 0.071386017 | I5: =STATEMENT!H9/STATEMENT!H7 -> 0.071386017 | J5: =STATEMENT!I9/STATEMENT!I7 -> 0.076759105 | K5: 0.15 | M5: Receivable turnover in days (RTD) | N5: =365/N4 -> 2.1481568 | O5: =365/O4 -> 2.3416912 | P5: =365/P4 -> 4.4862498 | Q5: =365/Q4 -> 28.076923 | R5: 365/RT
A6: Acid Test Ratio | B6: =(STATEMENT!C26-STATEMENT!C17)/STATEMENT!C42 -> 1.0754228 | C6: =(STATEMENT!D26-STATEMENT!D17)/STATEMENT!D42 -> 1.1769541 | D6: =(STATEMENT!E26-STATEMENT!E17)/STATEMENT!E42 -> 1.343222 | E6: 1.3 | G6: net profit margin | H6: =STATEMENT!H19/STATEMENT!H7 -> 0.036934944 | I6: =STATEMENT!I19/STATEMENT!I7 -> 0.060944875 | J6: =STATEMENT!J19/STATEMENT!J7 -> 0.074801525 | K6: 0.11 | M6: Payables Turnover | N6: =STATEMENT!H8/STATEMENT!C40 -> 2.7462298 | O6: =STATEMENT!I8/STATEMENT!D40 -> 3.338596 | P6: =STATEMENT!J8/STATEMENT!E40 -> 3.7160016 | Q6: =Q10-Q5-Q9 -> 99.123077 | R6: cost of Sales /trade and other payable
G7: return on investment (ROI) | H7: =STATEMENT!H19/STATEMENT!C27 -> 0.071449563 | I7: =STATEMENT!I19/STATEMENT!D27 -> 0.12783204 | J7: =STATEMENT!J19/STATEMENT!E27 -> 0.17462023 | K7: =23009659/184774378 -> 0.12452841 | M7: payable turnover in days (PTD) | N7: =365/N6 -> 132.90949 | O7: =365/O6 -> 109.32739 | P7: =365/P6 -> 98.223855 | Q7: 127.33 | R7: 365/PT
A8: current assets/ current libilitties | G8: Return on Equity (ROE) | H8: =STATEMENT!H19/STATEMENT!C32 -> 0.21967374 | I8: =STATEMENT!I19/STATEMENT!D32 -> 0.33746491 | J8: =STATEMENT!J19/STATEMENT!E32 -> 0.41943208 | K8: 0.3 | M8: inventory turnover (IT) | N8: =STATEMENT!H8/((STATEMENT!D17+STATEMENT!C17)/2) -> 14.275048 | O8: =STATEMENT!I8/((STATEMENT!D17+STATEMENT!C17)/2) -> 16.686247 | P8: =STATEMENT!J8/((STATEMENT!E17+STATEMENT!D17)/2) -> 20.200257 | Q8: 8.5 | R8: Cost of Sales / Average Inventory
A9: (current asset - inventory)/current libilties | M9: inventory turnover in days (ITD) | N9: =365/N8 -> 25.569091 | O9: =365/O8 -> 21.874301 | P9: =365/P8 -> 18.069077 | Q9: 43.2 | R9: 365/IT
M10: operating cycle | N10: =N5+N9 -> 27.717248 | O10: =O5+O9 -> 24.215992 | P10: =P5+P9 -> 22.555327 | Q10: 170.4 | R10: RTD+ITD
M11: cash cycle | N11: =N10-N7 -> -105.19224 | O11: =O10-O7 -> -85.111402 | P11: =P10-P7 -> -75.668529 | Q11: 43.2 | R11: Operating Cycle−PTD
M12: Total asset turnover | N12: =STATEMENT!H7/STATEMENT!C27 -> 1.9344706 | O12: =STATEMENT!I7/STATEMENT!D27 -> 2.0975027 | P12: =STATEMENT!J7/STATEMENT!E27 -> 2.3344474 | Q12: 1.2 | R12: Net Sales / Total Assets
A26: Coverage Ratio
B27: Atlas Honda Limited | E27: Indus Motors
B28: 2023 | C28: 2024 | D28: 2025 | E28: 2025
A29: Interest Coverage Ratio | B29: =STATEMENT!H15/STATEMENT!C17 -> 1.0216875 | C29: =STATEMENT!I15/STATEMENT!D17 -> 1.6463076 | D29: =STATEMENT!J15/STATEMENT!E17 -> 2.9233223 | E29: =22984791/21766847 -> 1.0559541
A31: EBIT/INTEREST EXP(financial cost)
G34: DEBT RATIO
H35: Atlas Honda Limited | K35: Indus Motors
H36: 2023 | I36: 2024 | J36: 2025 | K36: 2025
G37: Debt to Equity Ratio | H37: =(STATEMENT!C43-STATEMENT!C32)/(STATEMENT!C31+STATEMENT!C30) -> 2.0745288 | I37: =(STATEMENT!D43-STATEMENT!D32)/(STATEMENT!D30+STATEMENT!D31) -> 1.6399086 | J37: =(STATEMENT!E43-STATEMENT!E32)/(STATEMENT!E31+STATEMENT!E30) -> 1.4019673 | K37: 0.84
G38: Debt to Asset Ratio | H38: =STATEMENT!C42/STATEMENT!C27 -> 0.65560411 | I38: =STATEMENT!D42/STATEMENT!D27 -> 0.59709534 | J38: =STATEMENT!E42/STATEMENT!E27 -> 0.56047486 | K38: 0.35
G41: Shareholders’ Equity = Share Capital + Reserves
G42: Total liabilities = Total equity & liabilities – total equity

Sheet ANALYSIS
B2: Common Size Analysis | J2: Index Analysis
B3: Statement of Financial Position | J3: Statement of Financial Position
C4: Regular in PKR | F4: Common size (%) | K4: Regular in PKR | N4: Indexed (%)
B5: Category | C5: 2023 | D5: 2024 | E5: 2025 | F5: 2023 | G5: 2024 | H5: 2025 | J5: Category | K5: 2023 | L5: 2024 | M5: 2025 | N5: 2023 | O5: 2024 | P5: 2025
B6: Assets | J6: Assets
B7: Non Current Assets | J7: Non Current Assets
B8: Property, plant & equipment | C8: 12158765 | D8: 12445718 | E8: 12629323 | F8: =C8/$C$26 -> 0.17360343 | G8: =D8/$D$26 -> 0.16388073 | H8: =E8/$E$26 -> 0.14459683 | J8: Property, plant & equipment | K8: 12158765 | L8: 12445718 | M8: 12629323 | N8: =K8/$K$8 -> 1 | O8: =L8/$K$8 -> 1.0236005 | P8: =M8/$K$8 -> 1.0387011
B9: Intangible asset | C9: 35311 | D9: 7826 | E9: 23959 | F9: =C9/$C$26 -> 0.00050417214 | G9: =D9/$D$26 -> 0.00010304995 | H9: =E9/$E$26 -> 0.00027431364 | J9: Intangible asset | K9: 35311 | L9: 7826 | M9: 23959 | N9: =K9/$K$9 -> 1 | O9: =L9/$K$9 -> 0.22163065 | P9: =M9/$K$9 -> 0.67851378
B10: Long term investments | C10: 340816 | D10: 350593 | E10: 400519 | F10: =C10/$C$26 -> 0.0048661871 | G10: =D10/$D$26 -> 0.0046164824 | H10: =E10/$E$26 -> 0.0045856598 | J10: Long term investments | K10: 340816 | L10: 350593 | M10: 400519 | N10: =K10/$K$10 -> 1 | O10: =L10/$K$10 -> 1.028687 | P10: =M10/$K$10 -> 1.1751766
B11: Long term loans and advances | C11: 75469 | D11: 106531 | E11: 119841 | F11: =C11/$C$26 -> 0.00107755 | G11: =D11/$D$26 -> 0.0014027619 | H11: =E11/$E$26 -> 0.0013720949 | J11: Long term loans and advances | K11: 75469 | L11: 106531 | M11: 119841 | N11: =K11/$K$11 -> 1 | O11: =L11/$K$11 -> 1.4115862 | P11: =M11/$K$11 -> 1.58795
B12: Long term deposits | C12: 41662 | D12: 41672 | E12: 43887 | F12: =C12/$C$26 -> 0.00059485202 | G12: =D12/$D$26 -> 0.00054872189 | H12: =E12/$E$26 -> 0.00050247517 | J12: Long term deposits | K12: 41662 | L12: 41672 | M12: 43887 | N12: =K12/$K$12 -> 1 | O12: =L12/$K$12 -> 1.00024 | P12: =M12/$K$12 -> 1.053406
B13: Total non current assets | C13: 12652023 | D13: 12952340 | E13: 13217529 | F13: =C13/$C$26 -> 0.18064619 | G13: =D13/$D$26 -> 0.17055175 | H13: =E13/$E$26 -> 0.15133138 | J13: Total non current assets | K13: 12652023 | L13: 12952340 | M13: 13217529 | N13: =K13/$K$13 -> 1 | O13: =L13/$K$13 -> 1.0237367 | P13: =M13/$K$13 -> 1.0446969
B14: Current Assets | J14: Current Assets
B15: Stores, spares and loose tools | C15: 1083666 | D15: 1027714 | E15: 993123 | F15: =C15/$C$26 -> 0.015472635 | G15: =D15/$D$26 -> 0.013532568 | H15: =E15/$E$26 -> 0.011370557 | J15: Stores, spares and loose tools | K15: 1083666 | L15: 1027714 | M15: 993123 | N15: =K15/$K$15 -> 1 | O15: =L15/$K$15 -> 0.94836786 | P15: =M15/$K$15 -> 0.9164475
B16: Stock in trade | C16: 8005452 | D16: 9621651 | E16: 8369639 | F16: =C16/$C$26 -> 0.11430222 | G16: =D16/$D$26 -> 0.12669444 | H16: =E16/$E$26 -> 0.095826459 | J16: Stock in trade | K16: 8005452 | L16: 9621651 | M16: 8369639 | N16: =K16/$K$16 -> 1 | O16: =L16/$K$16 -> 1.2018873 | P16: =M16/$K$16 -> 1.0454924
B17: Trade debts | C17: 797382 | D17: 1021954 | E17: 2506086 | F17: =C17/$C$26 -> 0.011385058 | G17: =D17/$D$26 -> 0.013456722 | H17: =E17/$E$26 -> 0.028692916 | J17: Trade debts | K17: 797382 | L17: 1021954 | M17: 2506086 | N17: =K17/$K$17 -> 1 | O17: =L17/$K$17 -> 1.2816367 | P17: =M17/$K$17 -> 3.1428926
B18: Loans and advances | C18: 94502 | D18: 89211 | E18: 102015 | F18: =C18/$C$26 -> 0.0013493041 | G18: =D18/$D$26 -> 0.0011746983 | H18: =E18/$E$26 -> 0.0011679997 | J18: Loans and advances | K18: 94502 | L18: 89211 | M18: 102015 | N18: =K18/$K$18 -> 1 | O18: =L18/$K$18 -> 0.94401177 | P18: =M18/$K$18 -> 1.079501
B19: Trade deposits and prepayments | C19: 2242128 | D19: 229118 | E19: 290415 | F19: =C19/$C$26 -> 0.03201321 | G19: =D19/$D$26 -> 0.0030169433 | H19: =E19/$E$26 -> 0.0033250468 | J19: Trade deposits and prepayments | K19: 2242128 | L19: 229118 | M19: 290415 | N19: =K19/$K$19 -> 1 | O19: =L19/$K$19 -> 0.10218774 | P19: =M19/$K$19 -> 0.1295265
B20: Short term investments | C20: 10114241 | D20: 13959667 | E20: 30048664 | F20: =C20/$C$26 -> 0.14441161 | G20: =D20/$D$26 -> 0.18381587 | H20: =E20/$E$26 -> 0.34403599 | J20: Short term investments | K20: 10114241 | L20: 13959667 | M20: 30048664 | N20: =K20/$K$20 -> 1 | O20: =L20/$K$20 -> 1.3801992 | P20: =M20/$K$20 -> 2.9709262
B21: Accrued mark-up/interest | C21: 343803 | D21: 656355 | E21: 1063361 | F21: =C21/$C$26 -> 0.0049088356 | G21: =D21/$D$26 -> 0.0086426464 | H21: =E21/$E$26 -> 0.012174733 | J21: Accrued mark-up/interest | K21: 343803 | L21: 656355 | M21: 1063361 | N21: =K21/$K$21 -> 1 | O21: =L21/$K$21 -> 1.909102 | P21: =M21/$K$21 -> 3.0929369
B22: Other receivables | C22: 1874 | D22: 16137 | E22: 650643 | F22: =C22/$C$26 -> 2.6757061e-05 | G22: =D22/$D$26 -> 0.00021248621 | H22: =E22/$E$26 -> 0.0074494031 | J22: Other receivables | K22: 1874 | L22: 16137 | M22: 650643 | N22: =K22/$K$22 -> 1 | O22: =L22/$K$22 -> 8.6109925 | P22: =M22/$K$22 -> 347.19477
B23: Taxation - net | E23: 811 | H23: =E23/$E$26 -> 9.2853775e-06 | J23: Taxation - net | M23: 811
B24: Bank balances | C24: 34702516 | D24: 36369606 | E24: 30099343 | F24: =C24/$C$26 -> 0.49548417 | G24: =D24/$D$26 -> 0.47890188 | H24: =E24/$E$26 -> 0.34461623 | J24: Bank balances | K24: 34702516 | L24: 36369606 | M24: 30099343 | N24: =K24/$K$24 -> 1 | O24: =L24/$K$24 -> 1.0480395 | P24: =M24/$K$24 -> 0.86735334
B25: Total current assets | C25: 57385564 | D25: 62991413 | E25: 74124100 | F25: =C25/$C$26 -> 0.81935381 | G25: =D25/$D$26 -> 0.82944825 | H25: =E25/$E$26 -> 0.84866862 | J25: Total current assets | K25: 57385564 | L25: 62991413 | M25: 74124100 | N25: =K25/$K$25 -> 1 | O25: =L25/$K$25 -> 1.0976874 | P25: =M25/$K$25 -> 1.2916855
B26: Total assets | C26: 70037587 | D26: 75943753 | E26: 87341629 | F26: =C26/$C$26 -> 1 | G26: =D26/$D$26 -> 1 | H26: =E26/$E$26 -> 1 | J26: Total assets | K26: 70037587 | L26: 75943753 | M26: 87341629 | N26: =K26/$K$26 -> 1 | O26: =L26/$K$26 -> 1.0843285 | P26: =M26/$K$26 -> 1.2470679
B27: Equity & Liabilities | J27: Equity & Liabilities
B28: Equity | J28: Equity
B29: Share capital | C29: 1240879 | D29: 1240879 | E29: 1240879 | F29: =C29/$C$26 -> 0.017717329 | G29: =D29/$D$26 -> 0.016339448 | H29: =E29/$E$26 -> 0.014207189 | J29: Share capital | K29: 1240879 | L29: 1240879 | M29: 1240879 | N29: =K29/$K$29 -> 1 | O29: =L29/$K$29 -> 1 | P29: =M29/$K$29 -> 1
B30: Reserves | C30: 21539063 | D30: 27526690 | E30: 35121659 | F30: =C30/$C$26 -> 0.30753577 | G30: =D30/$D$26 -> 0.36246154 | H30: =E30/$E$26 -> 0.4021182 | J30: Reserves | K30: 21539063 | L30: 27526690 | M30: 35121659 | N30: =K30/$K$30 -> 1 | O30: =L30/$K$30 -> 1.2779892 | P30: =M30/$K$30 -> 1.6306029
B31: Total equity | C31: 22779942 | D31: 28767569 | E31: 36362538 | F31: =C31/$C$26 -> 0.3252531 | G31: =D31/$D$26 -> 0.37880099 | H31: =E31/$E$26 -> 0.41632539 | J31: Total equity | K31: 22779942 | L31: 28767569 | M31: 36362538 | N31: =K31/$K$31 -> 1 | O31: =L31/$K$31 -> 1.2628465 | P31: =M31/$K$31 -> 1.5962524
B32: Non Current Liabilities | J32: Non Current Liabilities
B33: Lease liabilities | C33: 148102 | D33: 289306 | E33: 355322 | F33: =C33/$C$26 -> 0.0021146074 | G33: =D33/$D$26 -> 0.0038094773 | H33: =E33/$E$26 -> 0.0040681861 | J33: Lease liabilities | K33: 148102 | L33: 289306 | M33: 355322 | N33: =K33/$K$33 -> 1 | O33: =L33/$K$33 -> 1.953424 | P33: =M33/$K$33 -> 2.3991708
B34: Staff retirement benefits | C34: 559591 | D34: 663559 | E34: 743615 | F34: =C34/$C$26 -> 0.0079898669 | G34: =D34/$D$26 -> 0.008737506 | H34: =E34/$E$26 -> 0.0085138669 | J34: Staff retirement benefits | K34: 559591 | L34: 663559 | M34: 743615 | N34: =K34/$K$34 -> 1 | O34: =L34/$K$34 -> 1.1857928 | P34: =M34/$K$34 -> 1.3288545
B35: Deferred taxation | C35: 633022 | D35: 877658 | E35: 927367 | F35: =C35/$C$26 -> 0.0090383182 | G35: =D35/$D$26 -> 0.011556685 | H35: =E35/$E$26 -> 0.010617698 | J35: Deferred taxation | K35: 633022 | L35: 877658 | M35: 927367 | N35: =K35/$K$35 -> 1 | O35: =L35/$K$35 -> 1.3864573 | P35: =M35/$K$35 -> 1.4649838
B36: Total non current liabilities | C36: 1340715 | D36: 1830523 | E36: 2026304 | F36: =C36/$C$26 -> 0.019142793 | G36: =D36/$D$26 -> 0.024103668 | H36: =E36/$E$26 -> 0.02319975 | J36: Total non current liabilities | K36: 1340715 | L36: 1830523 | M36: 2026304 | N36: =K36/$K$36 -> 1 | O36: =L36/$K$36 -> 1.3653334 | P36: =M36/$K$36 -> 1.5113607
B37: Current Liabilities | J37: Current Liabilities
B38: Current portion of lease liabilities | C38: 53617 | D38: 57987 | E38: 52285 | F38: =C38/$C$26 -> 0.00076554608 | G38: =D38/$D$26 -> 0.00076355194 | H38: =E38/$E$26 -> 0.00059862634 | J38: Current portion of lease liabilities | K38: 53617 | L38: 57987 | M38: 52285 | N38: =K38/$K$38 -> 1 | O38: =L38/$K$38 -> 1.081504 | P38: =M38/$K$38 -> 0.97515713
B39: Trade and other payables | C39: 45813308 | D39: 44049984 | E39: 48900502 | F39: =C39/$C$26 -> 0.65412459 | G39: =D39/$D$26 -> 0.58003433 | H39: =E39/$E$26 -> 0.55987623 | J39: Trade and other payables | K39: 45813308 | L39: 44049984 | M39: 48900502 | N39: =K39/$K$39 -> 1 | O39: =L39/$K$39 -> 0.96151066 | P39: =M39/$K$39 -> 1.0673864
B40: Taxation - net | C40: 50005 | D40: 1237690 | F40: =C40/$C$26 -> 0.00071397377 | G40: =D40/$D$26 -> 0.016297456 | J40: Taxation - net | K40: 50005 | L40: 1237690 | N40: =K40/$K$40 -> 1 | O40: =L40/$K$40 -> 24.751325 | P40: =M40/$K$40 -> 0
B41: Total current liabilities | C41: 45916930 | D41: 45345661 | E41: 48952787 | F41: =C41/$C$26 -> 0.65560411 | G41: =D41/$D$26 -> 0.59709534 | H41: =E41/$E$26 -> 0.56047486 | J41: Total current liabilities | K41: 45916930 | L41: 45345661 | M41: 48952787 | N41: =K41/$K$41 -> 1 | O41: =L41/$K$41 -> 0.98755864 | P41: =M41/$K$41 -> 1.0661163
...

Sheet S.D
A1: ATLAS HONDA LIMITED | G1: INDUS MOTORS
A2: DATE | B2: CLOSE | C2: RETURN | D2: DEVIATION | E2: (X-X')^2 | G2: DATE | H2: CLOSE | I2: RETURN | J2: DEVIATION | K2: (X-X')^2
A3: Nov 27, 2:34 | B3: 1424.51 | C3: =B3-B4/B4 -> 1423.51 | D3: =B3-$C48 -> -11.795476 | E3: =D3^2 -> 139.13326 | G3: Nov 24,2025 | H3: 2018.61 | I3: =H3-H4/H4 -> 2017.61 | J3: =H3-$I$48 -> -57.605385 | K3: =J3^2 -> 3318.3803
A4: Nov 26, 2025 | B4: 1425.89 | C4: =B4-B5/B5 -> 1424.89 | D4: =B4-$C48 -> -10.415476 | E4: =D4^2 -> 108.48214 | G4: Nov 21,2025 | H4: 2013.23 | I4: =H4-H5/H5 -> 2012.23 | J4: =H4-$I$48 -> -62.985385 | K4: =J4^2 -> 3967.1587
A5: Nov 25, 2025 | B5: 1459.76 | C5: =B5-B6/B6 -> 1458.76 | D5: =B5-$C48 -> 23.454524 | E5: =D5^2 -> 550.11469 | G5: Nov 20,2025 | H5: 2019.98 | I5: =H5-H6/H6 -> 2018.98 | J5: =H5-$I$48 -> -56.235385 | K5: =J5^2 -> 3162.4185
A6: Nov 24, 2025 | B6: 1458.83 | C6: =B6-B7/B7 -> 1457.83 | D6: =B6-$C48 -> 22.524524 | E6: =D6^2 -> 507.35417 | G6: Nov 19,2025 | H6: 2023.31 | I6: =H6-H7/H7 -> 2022.31 | J6: =H6-$I$48 -> -52.905385 | K6: =J6^2 -> 2798.9797
A7: Nov 21, 2025 | B7: 1471.19 | C7: =B7-B8/B8 -> 1470.19 | D7: =B7-$C48 -> 34.884524 | E7: =D7^2 -> 1216.93 | G7: Nov 18,2025 | H7: 2022.3 | I7: =H7-H8/H8 -> 2021.3 | J7: =H7-$I$48 -> -53.915385 | K7: =J7^2 -> 2906.8687
A8: Nov 20, 2025 | B8: 1487.23 | C8: =B8-B9/B9 -> 1486.23 | D8: =B8-C48 -> 50.924524 | E8: =D8^2 -> 2593.3071 | G8: Nov 17,2025 | H8: 2028.91 | I8: =H8-H9/H9 -> 2027.91 | J8: =H8-$I$48 -> -47.305385 | K8: =J8^2 -> 2237.7994
A9: Nov 19, 2025 | B9: 1489.23 | C9: =B9-B10/B10 -> 1488.23 | D9: =B9-C48 -> 52.924524 | E9: =D9^2 -> 2801.0052 | G9: Nov 14,2025 | H9: 2014.06 | I9: =H9-H10/H10 -> 2013.06 | J9: =H9-$I$48 -> -62.155385 | K9: =J9^2 -> 3863.2918
A10: Nov 18, 2025 | B10: 1486.16 | C10: =B10-B11/B11 -> 1485.16 | D10: =B10-C48 -> 49.854524 | E10: =D10^2 -> 2485.4735 | G10: Nov 13,2025 | H10: 2002.15 | I10: =H10-H11/H11 -> 2001.15 | J10: =H10-$I$48 -> -74.065385 | K10: =J10^2 -> 5485.6812
A11: Nov 17, 2025 | B11: 1488.42 | C11: =B11-B12/B12 -> 1487.42 | D11: =B11-C48 -> 52.114524 | E11: =D11^2 -> 2715.9236 | G11: Nov 12,2025 | H11: 1998.25 | I11: =H11-H12/H12 -> 1997.25 | J11: =H11-$I$48 -> -77.965385 | K11: =J11^2 -> 6078.6012
A12: Nov 14, 2025 | B12: 1487.95 | C12: =B12-B13/B13 -> 1486.95 | D12: =B12-C48 -> 51.644524 | E12: =D12^2 -> 2667.1568 | G12: Nov 11,2025 | H12: 1992.84 | I12: =H12-H13/H13 -> 1991.84 | J12: =H12-$I$48 -> -83.375385 | K12: =J12^2 -> 6951.4548
A13: Nov 13, 2025 | B13: 1478.3 | C13: =B13-B14/B14 -> 1477.3 | D13: =B13-C48 -> 41.994524 | E13: =D13^2 -> 1763.54 | G13: Nov 10,2025 | H13: 2002.03 | I13: =H13-H14/H14 -> 2001.03 | J13: =H13-$I$48 -> -74.185385 | K13: =J13^2 -> 5503.4713
A14: Nov 12, 2025 | B14: 1479.52 | C14: =B14-B15/B15 -> 1478.52 | D14: =B14-C48 -> 43.214524 | E14: =D14^2 -> 1867.4951 | G14: Nov 7, 2025 | H14: 1998.99 | I14: =H14-H15/H15 -> 1997.99 | J14: =H14-$I$48 -> -77.225385 | K14: =J14^2 -> 5963.76
A15: Nov 11, 2025 | B15: 1468.34 | C15: =B15-B16/B16 -> 1467.34 | D15: =B15-C48 -> 32.034524 | E15: =D15^2 -> 1026.2107 | G15: Nov 6, 2025 | H15: 1998.3 | I15: =H15-H16/H16 -> 1997.3 | J15: =H15-$I$48 -> -77.915385 | K15: =J15^2 -> 6070.8072
A16: Nov 10, 2025 | B16: 1538.22 | C16: =B16-B17/B17 -> 1537.22 | D16: =B16-C48 -> 101.91452 | E16: =D16^2 -> 10386.57 | G16: Nov 5, 2025 | H16: 2002.05 | I16: =H16-H17/H17 -> 2001.05 | J16: =H16-$I$48 -> -74.165385 | K16: =J16^2 -> 5500.5043
A17: Nov 7, 2025 | B17: 1527.01 | C17: =B17-B18/B18 -> 1526.01 | D17: =B17-C48 -> 90.704524 | E17: =D17^2 -> 8227.3106 | G17: Nov 4, 2025 | H17: 2065.15 | I17: =H17-H18/H18 -> 2064.15 | J17: =H17-$I$48 -> -11.065385 | K17: =J17^2 -> 122.44274
A18: Nov 6, 2025 | B18: 1515.53 | C18: =B18-B19/B19 -> 1514.53 | D18: =B18-C48 -> 79.224524 | E18: =D18^2 -> 6276.5252 | G18: Nov 3, 2025 | H18: 2076.73 | I18: =H18-H19/H19 -> 2075.73 | J18: =H18-$I$48 -> 0.51461538 | K18: =J18^2 -> 0.26482899
A19: Nov 5, 2025 | B19: 1515.08 | C19: =B19-B20/B20 -> 1514.08 | D19: =B19-C48 -> 78.774524 | E19: =D19^2 -> 6205.4256 | G19: Oct 31, 2025 | H19: 2079.2 | I19: =H19-H20/H20 -> 2078.2 | J19: =H19-$I$48 -> 2.9846154 | K19: =J19^2 -> 8.907929
A20: Nov 4, 2025 | B20: 1506.67 | C20: =B20-B21/B21 -> 1505.67 | D20: =B20-C48 -> 70.364524 | E20: =D20^2 -> 4951.1662 | G20: Oct 30, 2025 | H20: 2079.78 | I20: =H20-H21/H21 -> 2078.78 | J20: =H20-$I$48 -> 3.5646154 | K20: =J20^2 -> 12.706483
A21: Nov 3, 2025 | B21: 1526.51 | C21: =B21-B22/B22 -> 1525.51 | D21: =B21-C48 -> 90.204524 | E21: =D21^2 -> 8136.8561 | G21: Oct 29, 2025 | H21: 2077.74 | I21: =H21-H22/H22 -> 2076.74 | J21: =H21-$I$48 -> 1.5246154 | K21: =J21^2 -> 2.3244521
A22: Oct 31, 2025 | B22: 1454.71 | C22: =B22-B23/B23 -> 1453.71 | D22: =B22-C48 -> 18.404524 | E22: =D22^2 -> 338.7265 | G22: Oct 28, 2025 | H22: 2089.55 | I22: =H22-H23/H23 -> 2088.55 | J22: =H22-$I$48 -> 13.334615 | K22: =J22^2 -> 177.81197
A23: Oct 30, 2025 | B23: 1433.35 | C23: =B23-B24/B24 -> 1432.35 | D23: =B23-C48 -> -2.9554762 | E23: =D23^2 -> 8.7348395 | G23: Oct 27, 2025 | H23: 2070.4 | I23: =H23-H24/H24 -> 2069.4 | J23: =H23-$I$48 -> -5.8153846 | K23: =J23^2 -> 33.818698
A24: Oct 29, 2025 | B24: 1397.17 | C24: =B24-B25/B25 -> 1396.17 | D24: =B24-C48 -> -39.135476 | E24: =D24^2 -> 1531.5855 | G24: Oct 24, 2025 | H24: 2076.06 | I24: =H24-H25/H25 -> 2075.06 | J24: =H24-$I$48 -> -0.15538462 | K24: =J24^2 -> 0.024144379
A25: Oct 28, 2025 | B25: 1398.44 | C25: =B25-B26/B26 -> 1397.44 | D25: =B25-C48 -> -37.865476 | E25: =D25^2 -> 1433.7943 | G25: Oct 23, 2025 | H25: 2080.55 | I25: =H25-H26/H26 -> 2079.55 | J25: =H25-$I$48 -> 4.3346154 | K25: =J25^2 -> 18.788891
A26: Oct 27, 2025 | B26: 1389.11 | C26: =B26-B27/B27 -> 1388.11 | D26: =B26-C48 -> -47.195476 | E26: =D26^2 -> 2227.413 | G26: Oct 22, 2025 | H26: 2080.06 | I26: =H26-H27/H27 -> 2079.06 | J26: =H26-$I$48 -> 3.8446154 | K26: =J26^2 -> 14.781067
A27: Oct 24, 2025 | B27: 1398.07 | C27: =B27-B28/B28 -> 1397.07 | D27: =B27-C48 -> -38.235476 | E27: =D27^2 -> 1461.9516 | G27: Oct 21, 2025 | H27: 2117.27 | I27: =H27-H28/H28 -> 2116.27 | J27: =H27-$I$48 -> 41.054615 | K27: =J27^2 -> 1685.4814
A28: Oct 23, 2025 | B28: 1394.47 | C28: =B28-B29/B29 -> 1393.47 | D28: =B28-C48 -> -41.835476 | E28: =D28^2 -> 1750.2071 | G28: Oct 20, 2025 | H28: 2106.74 | I28: =H28-H29/H29 -> 2105.74 | J28: =H28-$I$48 -> 30.524615 | K28: =J28^2 -> 931.75214
A29: Oct 22, 2025 | B29: 1394.86 | C29: =B29-B30/B30 -> 1393.86 | D29: =B29-C48 -> -41.445476 | E29: =D29^2 -> 1717.7275 | G29: Oct 17, 2025 | H29: 2107.47 | I29: =H29-H30/H30 -> 2106.47 | J29: =H29-$I$48 -> 31.254615 | K29: =J29^2 -> 976.85098
A30: Oct 21, 2025 | B30: 1385.83 | C30: =B30-B31/B31 -> 1384.83 | D30: =B30-C48 -> -50.475476 | E30: =D30^2 -> 2547.7737 | G30: Oct 16, 2025 | H30: 2101.31 | I30: =H30-H31/H31 -> 2100.31 | J30: =H30-$I$48 -> 25.094615 | K30: =J30^2 -> 629.73972
A31: Oct 20, 2025 | B31: 1383.95 | C31: =B31-B32/B32 -> 1382.95 | D31: =B31-C48 -> -52.355476 | E31: =D31^2 -> 2741.0959 | G31: Oct 15, 2025 | H31: 2109.36 | I31: =H31-H32/H32 -> 2108.36 | J31: =H31-$I$48 -> 33.144615 | K31: =J31^2 -> 1098.5655
A32: Oct 17, 2025 | B32: 1387.71 | C32: =B32-B33/B33 -> 1386.71 | D32: =B32-C48 -> -48.595476 | E32: =D32^2 -> 2361.5203 | G32: Oct 14, 2025 | H32: 2104.78 | I32: =H32-H33/H33 -> 2103.78 | J32: =H32-$I$48 -> 28.564615 | K32: =J32^2 -> 815.93725
A33: Oct 16, 2025 | B33: 1388.77 | C33: =B33-B34/B34 -> 1387.77 | D33: =B33-C48 -> -47.535476 | E33: =D33^2 -> 2259.6215 | G33: Oct 13, 2025 | H33: 2037.76 | I33: =H33-H34/H34 -> 2036.76 | J33: =H33-$I$48 -> -38.455385 | K33: =J33^2 -> 1478.8166
A34: Oct 15, 2025 | B34: 1380.64 | C34: =B34-B35/B35 -> 1379.64 | D34: =B34-C48 -> -55.665476 | E34: =D34^2 -> 3098.6452 | G34: Oct 10, 2025 | H34: 2107.42 | I34: =H34-H35/H35 -> 2106.42 | J34: =H34-$I$48 -> 31.204615 | K34: =J34^2 -> 973.72802
A35: Oct 14, 2025 | B35: 1392.09 | C35: =B35-B36/B36 -> 1391.09 | D35: =B35-C48 -> -44.215476 | E35: =D35^2 -> 1955.0083 | G35: Oct 9, 2025 | H35: 2145.86 | I35: =H35-H36/H36 -> 2144.86 | J35: =H35-$I$48 -> 69.644615 | K35: =J35^2 -> 4850.3725
A36: Oct 13, 2025 | B36: 1379.98 | C36: =B36-B37/B37 -> 1378.98 | D36: =B36-C48 -> -56.325476 | E36: =D36^2 -> 3172.5593 | G36: Oct 8, 2025 | H36: 2150.96 | I36: =H36-H37/H37 -> 2149.96 | J36: =H36-$I$48 -> 74.744615 | K36: =J36^2 -> 5586.7575
A37: Oct 10, 2025 | B37: 1371.94 | C37: =B37-B38/B38 -> 1370.94 | D37: =B37-C48 -> -64.365476 | E37: =D37^2 -> 4142.9145 | G37: Oct 7, 2025 | H37: 2168.62 | I37: =H37-H38/H38 -> 2167.62 | J37: =H37-$I$48 -> 92.404615 | K37: =J37^2 -> 8538.6129
A38: Oct 9, 2025 | B38: 1393.7 | C38: =B38-B39/B39 -> 1392.7 | D38: =B38-C48 -> -42.605476 | E38: =D38^2 -> 1815.2266 | G38: Oct 6, 2025 | H38: 2179.91 | I38: =H38-H39/H39 -> 2178.91 | J38: =H38-$I$48 -> 103.69462 | K38: =J38^2 -> 10752.573
A39: Oct 8, 2025 | B39: 1401.79 | C39: =B39-B40/B40 -> 1400.79 | D39: =B39-C48 -> -34.515476 | E39: =D39^2 -> 1191.3181 | G39: Oct 3, 2025 | H39: 2204.48 | I39: =H39-H40/H40 -> 2203.48 | J39: =H39-$I$48 -> 128.26462 | K39: =J39^2 -> 16451.812
A40: Oct 7, 2025 | B40: 1405.92 | C40: =B40-B41/B41 -> 1404.92 | D40: =B40-C48 -> -30.385476 | E40: =D40^2 -> 923.27716 | G40: Oct 2, 2025 | H40: 2209.18 | I40: =H40-H41/H41 -> 2208.18 | J40: =H40-$I$48 -> 132.96462 | K40: =J40^2 -> 17679.589
...
